Workbook
Name SlicerCache_Table_8_Col_2: #N/A

Sheet Home
A1: HOME | B1: DASHBOARD | C1: ENTRY DATA | D1: DATA BASE | E1: GRAPH | F1: JADWAL | G1: KALENDER | H1: TRACKER
K2: *
A3: * | D3: * | L3: *
G4: *
F5: * | K5: *
C6: * | I6: * | O6: *
B8: * | J8: * | K8: * | M8: *
H9: * | K9: *
A10: * | E10: * | F10: KALENDER PERKULIAHAN | K10: * | N10: *
D11: * | F11: * | G11: _NAMA_JURUSAN | I11: * | L11: *
F12: * | G12: TAHUN 2025
E13: * | J13: * | K13: *
B14: * | F14: * | I14: * | K14: * | O14: *
F15: *
G16: * | J16: * | N16: *
H17: *
I18: * | M18: *
C19: * | F19: *
A21: * | E21: * | I21: *
A22: Anggota Kelompok : M. Haekal Fallah Ar-Rahman (061) Maydina Aulia Putri (143) Vierico Ventora (203) | L22: *
O23: *

Sheet Dashboard
A1: HOME | B1: DASHBOARD | C1: ENTRY DATA | D1: DATA BASE | E1: GRAPH | F1: JADWAL | G1: KALENDER | H1: TRACKER | Q1: *
J3: * | N3: * | U3: *
C4: SEMESTER AKTIF/SAAT INI : | E4: 1 | K4: *
H6: JADWAL KULIAH SEMESTER INI | O6: AGENDA PRIORITAS
B7: RATA RATA KEHADIRAN : | F7: Semester | G7: Mata Kuliah | H7: Hari | I7: SKS | J7: Waktu | K7: Keterangan | M7: Kegiatan | N7: Mata Kuliah | O7: Prioritas | P7: Deadline | Q7: Progress
A8: * | B8: =IFERROR(AVERAGEIF(Database!B:B, E4, Database!H:H), "") -> 0.97115385 | F8: =IFERROR(__xludf.DUMMYFUNCTION("FILTER(Database!B6:G60, Database!B6:B60 = E4) "),1.0) -> 1 | G8: =IFERROR(__xludf.DUMMYFUNCTION("""COMPUTED_VALUE"""),"Literasi Digital") -> Literasi Digital | H8: =IFERROR(__xludf.DUMMYFUNCTION("""COMPUTED_VALUE"""),"Senin") -> Senin | I8: =IFERROR(__xludf.DUMMYFUNCTION("""COMPUTED_VALUE"""),3.0) -> 3 | J8: =IFERROR(__xludf.DUMMYFUNCTION("""COMPUTED_VALUE"""),"07.00-08.40") -> 07.00-08.40 | K8: =IFERROR(__xludf.DUMMYFUNCTION("""COMPUTED_VALUE"""),"Online") -> Online | M8: =IFERROR(__xludf.DUMMYFUNCTION("QUERY( 'Entry Data'!H:Q, ""select J, K, M, O, Q where L <> 'Selesai' and M = 'Tinggi' and O >= date '"" & TEXT(TODAY(),""yyyy-MM-dd"") & ""' order by O asc limit 3"", 1 )"),"#N/A") -> #N/A | S8: *
F9: =IFERROR(__xludf.DUMMYFUNCTION("""COMPUTED_VALUE"""),1.0) -> 1 | G9: =IFERROR(__xludf.DUMMYFUNCTION("""COMPUTED_VALUE"""),"Matematika Diskrit") -> Matematika Diskrit | H9: =IFERROR(__xludf.DUMMYFUNCTION("""COMPUTED_VALUE"""),"Senin") -> Senin | I9: =IFERROR(__xludf.DUMMYFUNCTION("""COMPUTED_VALUE"""),3.0) -> 3 | J9: =IFERROR(__xludf.DUMMYFUNCTION("""COMPUTED_VALUE"""),"09.30-12.00") -> 09.30-12.00 | K9: =IFERROR(__xludf.DUMMYFUNCTION("""COMPUTED_VALUE"""),"E2.01.08") -> E2.01.08
F10: =IFERROR(__xludf.DUMMYFUNCTION("""COMPUTED_VALUE"""),1.0) -> 1 | G10: =IFERROR(__xludf.DUMMYFUNCTION("""COMPUTED_VALUE"""),"Pancasila") -> Pancasila | H10: =IFERROR(__xludf.DUMMYFUNCTION("""COMPUTED_VALUE"""),"Selasa") -> Selasa | I10: =IFERROR(__xludf.DUMMYFUNCTION("""COMPUTED_VALUE"""),3.0) -> 3 | J10: =IFERROR(__xludf.DUMMYFUNCTION("""COMPUTED_VALUE"""),"10.20-12.00") -> 10.20-12.00 | K10: =IFERROR(__xludf.DUMMYFUNCTION("""COMPUTED_VALUE"""),"Online") -> Online | U10: *
F11: =IFERROR(__xludf.DUMMYFUNCTION("""COMPUTED_VALUE"""),1.0) -> 1 | G11: =IFERROR(__xludf.DUMMYFUNCTION("""COMPUTED_VALUE"""),"Pemograman Dasar") -> Pemograman Dasar | H11: =IFERROR(__xludf.DUMMYFUNCTION("""COMPUTED_VALUE"""),"Selasa") -> Selasa | I11: =IFERROR(__xludf.DUMMYFUNCTION("""COMPUTED_VALUE"""),2.0) -> 2 | J11: =IFERROR(__xludf.DUMMYFUNCTION("""COMPUTED_VALUE"""),"13.00-15.30") -> 13.00-15.30 | K11: =IFERROR(__xludf.DUMMYFUNCTION("""COMPUTED_VALUE"""),"E2.01.07") -> E2.01.07 | O11: AGENDA TERDEKAT
F12: =IFERROR(__xludf.DUMMYFUNCTION("""COMPUTED_VALUE"""),1.0) -> 1 | G12: =IFERROR(__xludf.DUMMYFUNCTION("""COMPUTED_VALUE"""),"Praktikum") -> Praktikum | H12: =IFERROR(__xludf.DUMMYFUNCTION("""COMPUTED_VALUE"""),"Rabu") -> Rabu | I12: =IFERROR(__xludf.DUMMYFUNCTION("""COMPUTED_VALUE"""),2.0) -> 2 | J12: =IFERROR(__xludf.DUMMYFUNCTION("""COMPUTED_VALUE"""),"15.30-17.10") -> 15.30-17.10 | K12: =IFERROR(__xludf.DUMMYFUNCTION("""COMPUTED_VALUE"""),"C1.04") -> C1.04 | M12: Kegiatan | N12: Mata Kuliah | O12: Status | P12: Deadline | Q12: Progress
B13: PROGRESS SEMESTER : | F13: =IFERROR(__xludf.DUMMYFUNCTION("""COMPUTED_VALUE"""),1.0) -> 1 | G13: =IFERROR(__xludf.DUMMYFUNCTION("""COMPUTED_VALUE"""),"Arsitektur Komputer dan Sistem Operasi") -> Arsitektur Komputer dan Sistem Operasi | H13: =IFERROR(__xludf.DUMMYFUNCTION("""COMPUTED_VALUE"""),"Kamis") -> Kamis | I13: =IFERROR(__xludf.DUMMYFUNCTION("""COMPUTED_VALUE"""),3.0) -> 3 | J13: =IFERROR(__xludf.DUMMYFUNCTION("""COMPUTED_VALUE"""),"07.00-09.30") -> 07.00-09.30 | K13: =IFERROR(__xludf.DUMMYFUNCTION("""COMPUTED_VALUE"""),"E2.01.08") -> E2.01.08 | M13: =IFERROR(__xludf.DUMMYFUNCTION("INDEX( SORT( FILTER('Entry Data'!J:Q, 'Entry Data'!O:O >= TODAY()), 6, TRUE ), ROWS($Q$17:Q17), 1 )"),"Libur Semester") -> Libur Semester | N13: =IFERROR(__xludf.DUMMYFUNCTION("INDEX( SORT( FILTER('Entry Data'!J:Q, 'Entry Data'!O:O >= TODAY()), 6, TRUE ), ROWS($N$13:N13), 2 )"),"Lain-lain") -> Lain-lain | O13: =IFERROR(__xludf.DUMMYFUNCTION("INDEX( SORT( FILTER('Entry Data'!J:Q, 'Entry Data'!O:O >= TODAY()), 6, TRUE ), ROWS($N$13:N13), 3 ) "),"Belum dimulai") -> Belum dimulai | P13: =IFERROR(__xludf.DUMMYFUNCTION("INDEX( SORT( FILTER('Entry Data'!J:Q, 'Entry Data'!O:O >= TODAY()), 6, TRUE ), ROWS($N$13:N13), 6 ) "),46075.0) -> 46075 | Q13: =IFERROR(__xludf.DUMMYFUNCTION("INDEX( SORT( FILTER('Entry Data'!J:Q, 'Entry Data'!O:O >= TODAY()), 6, TRUE ), ROWS($N$13:N13), 8 ) "),0.0) -> 0 | S13: *
B14: =IFERROR(AVERAGEIF(Database!B:B, E4, Database!I:I), "") -> 0.8125 | F14: =IFERROR(__xludf.DUMMYFUNCTION("""COMPUTED_VALUE"""),1.0) -> 1 | G14: =IFERROR(__xludf.DUMMYFUNCTION("""COMPUTED_VALUE"""),"Aljabar Matriks") -> Aljabar Matriks | H14: =IFERROR(__xludf.DUMMYFUNCTION("""COMPUTED_VALUE"""),"Kamis") -> Kamis | I14: =IFERROR(__xludf.DUMMYFUNCTION("""COMPUTED_VALUE"""),3.0) -> 3 | J14: =IFERROR(__xludf.DUMMYFUNCTION("""COMPUTED_VALUE"""),"09.30-12.00") -> 09.30-12.00 | K14: =IFERROR(__xludf.DUMMYFUNCTION("""COMPUTED_VALUE"""),"E2.01.07") -> E2.01.07 | M14: =IFERROR(__xludf.DUMMYFUNCTION("INDEX( SORT( FILTER('Entry Data'!J:Q, 'Entry Data'!O:O >= TODAY()), 6, TRUE ), ROWS($Q$17:Q18), 1 )"),"") | N14: =IFERROR(__xludf.DUMMYFUNCTION("INDEX( SORT( FILTER('Entry Data'!J:Q, 'Entry Data'!O:O >= TODAY()), 6, TRUE ), ROWS($N$13:N14), 2 )"),"") | O14: =IFERROR(__xludf.DUMMYFUNCTION("INDEX( SORT( FILTER('Entry Data'!J:Q, 'Entry Data'!O:O >= TODAY()), 6, TRUE ), ROWS($N$13:N14), 3 ) "),"") | P14: =IFERROR(__xludf.DUMMYFUNCTION("INDEX( SORT( FILTER('Entry Data'!J:Q, 'Entry Data'!O:O >= TODAY()), 6, TRUE ), ROWS($N$13:N14), 6 ) ")," *") -> * | Q14: =IFERROR(__xludf.DUMMYFUNCTION("INDEX( SORT( FILTER('Entry Data'!J:Q, 'Entry Data'!O:O >= TODAY()), 6, TRUE ), ROWS($N$13:N14), 8 ) "),"")
F15: =IFERROR(__xludf.DUMMYFUNCTION("""COMPUTED_VALUE"""),1.0) -> 1 | G15: =IFERROR(__xludf.DUMMYFUNCTION("""COMPUTED_VALUE"""),"Matematika Dasar") -> Matematika Dasar | H15: =IFERROR(__xludf.DUMMYFUNCTION("""COMPUTED_VALUE"""),"Jumat") -> Jumat | I15: =IFERROR(__xludf.DUMMYFUNCTION("""COMPUTED_VALUE"""),3.0) -> 3 | J15: =IFERROR(__xludf.DUMMYFUNCTION("""COMPUTED_VALUE"""),"13.00-15.30") -> 13.00-15.30 | K15: =IFERROR(__xludf.DUMMYFUNCTION("""COMPUTED_VALUE"""),"E2.01.10") -> E2.01.10 | L15: * | M15: =IFERROR(__xludf.DUMMYFUNCTION("INDEX( SORT( FILTER('Entry Data'!J:Q, 'Entry Data'!O:O >= TODAY()), 6, TRUE ), ROWS($Q$17:Q19), 1 )"),"") | N15: =IFERROR(__xludf.DUMMYFUNCTION("INDEX( SORT( FILTER('Entry Data'!J:Q, 'Entry Data'!O:O >= TODAY()), 6, TRUE ), ROWS($N$13:N15), 2 )"),"") | O15: =IFERROR(__xludf.DUMMYFUNCTION("INDEX( SORT( FILTER('Entry Data'!J:Q, 'Entry Data'!O:O >= TODAY()), 6, TRUE ), ROWS($N$13:N15), 3 ) "),"") | P15: =IFERROR(__xludf.DUMMYFUNCTION("INDEX( SORT( FILTER('Entry Data'!J:Q, 'Entry Data'!O:O >= TODAY()), 6, TRUE ), ROWS($N$13:N15), 6 ) "),"*") -> * | Q15: =IFERROR(__xludf.DUMMYFUNCTION("INDEX( SORT( FILTER('Entry Data'!J:Q, 'Entry Data'!O:O >= TODAY()), 6, TRUE ), ROWS($N$13:N15), 8 ) "),"")
M16: =IFERROR(__xludf.DUMMYFUNCTION("INDEX( SORT( FILTER('Entry Data'!J:Q, 'Entry Data'!O:O >= TODAY()), 6, TRUE ), ROWS($Q$17:Q20), 1 )"),"Nama Kegiatan") -> Nama Kegiatan | N16: =IFERROR(__xludf.DUMMYFUNCTION("INDEX( SORT( FILTER('Entry Data'!J:Q, 'Entry Data'!O:O >= TODAY()), 6, TRUE ), ROWS($N$13:N16), 2 )"),"Mata Kuliah") -> Mata Kuliah | O16: =IFERROR(__xludf.DUMMYFUNCTION("INDEX( SORT( FILTER('Entry Data'!J:Q, 'Entry Data'!O:O >= TODAY()), 6, TRUE ), ROWS($N$13:N16), 3 ) "),"Status") -> Status | P16: =IFERROR(__xludf.DUMMYFUNCTION("INDEX( SORT( FILTER('Entry Data'!J:Q, 'Entry Data'!O:O >= TODAY()), 6, TRUE ), ROWS($N$13:N16), 6 ) "),"Deadline") -> Deadline | Q16: =IFERROR(__xludf.DUMMYFUNCTION("INDEX( SORT( FILTER('Entry Data'!J:Q, 'Entry Data'!O:O >= TODAY()), 6, TRUE ), ROWS($N$13:N16), 8 ) "),"Progress") -> Progress
D18: * | S18: *
H20: *
O21: *
C22: * | K22: *
B23: * | G23: * | T23: *
R24: *
E25: * | M25: *
P26: *
I27: *
S28: *

Sheet Entry Data
A1: HOME | B1: DASHBOARD | C1: ENTRY DATA | D1: DATA BASE | E1: GRAPH | F1: JADWAL | G1: KALENDER | H1: TRACKER | P1: * | V1: *
K2: *
D3: *
B4: * | F4: * | N4: *
U5: *
B6: Jadwal akademik resmi {JAR} | C6: Jadwal akademik pribadi {JAP} | D6: Tugas & Project {T&P} | E6: Jadwal Ujian, presentasi,& Praktikum {UPP} | F6: Agenda Pribadi {AP} | H6: Kategori | I6: Jenis Kegiatan | J6: Nama Kegiatan | K6: Mata Kuliah | L6: Status | M6: Prioritas | N6: Tanggal | O6: Deadline | P6: Catatan | Q6: Progress
B7: Awal Semester | C7: Aljabar Matriks | D7: Pr Matdas | E7: Quiz Matdis | F7: Badminton | H7: Non-Akademik | I7: JAR, Kuliah | J7: Awal semester | K7: Lain-lain | L7: Selesai | M7: Ringan | Q7: 1
B8: KRS | C8: Arsitektur Komputer & Sistem informasi | D8: Project Pemdas | E8: Praktikum Pemdas | F8: Pantai | H8: Akademik | I8: Praktikum, Tugas | J8: Praktikum Pemdas | K8: Praktikum | L8: Selesai | M8: Ringan | N8: 45945 | O8: 45952 | Q8: 1 | S8: * | W8: *
A9: * | B9: Revisi KRS | C9: Matematika Diskrit | D9: After Movie | E9: Presentasi Pancasila | G9: * | H9: Non-Akademik | I9: Tugas, Kegiatan Pribadi, AP | J9: After Movie | K9: Lain-lain | L9: Dalam proses | M9: Sedang | N9: 45955 | O9: 45981 | Q9: 0.3 | X9: *
B10: UTS | C10: Matematika Dasar | D10: UI&UX Design Kompetisi | H10: Akademik | I10: T&P, Kuliah | J10: Video Matdis | K10: Matematika Diskrit | L10: Dalam proses | M10: Sedang | N10: 45957 | O10: 45964 | Q10: 0.75
B11: UAS | C11: Pemograman Dasar | H11: Akademik | I11: T&P, Kuliah | J11: Soal Matdas | K11: Matematika Dasar | L11: Dalam proses | M11: Sedang | N11: 45957 | O11: 45959 | Q11: 0.9 | U11: *
B12: Akhir Semester | C12: Pancasila | H12: Akademik | I12: UPP, Kuliah | J12: Kuis Pancasila | K12: Pancasila | L12: Dalam proses | M12: Tinggi | N12: 45965 | O12: 45972 | Q12: 0.92 | X12: *
B13: Libur Semester | C13: Literasi Digital | H13: Akademik | I13: UPP, Kuliah | J13: Kuis Matdas | K13: Matematika Dasar | L13: Dalam proses | M13: Tinggi | N13: 45975 | O13: 45975 | Q13: 0.6 | S13: *
B14: Libur Resmi/Akademik | H14: Akademik | I14: UPP, Kuliah | J14: Presentasi Pancasila | K14: Pancasila | L14: Dalam proses | M14: Sedang | N14: 45965 | O14: 45979 | Q14: 0.4 | W14: *
H15: Non-Akademik | I15: Kegiatan Pribadi | J15: LKMM-TD | K15: Lain-lain | L15: Belum dimulai | M15: Ringan | N15: 45976 | O15: 45977
H16: Akademik | I16: UPP, Kuliah | J16: Kuis Aljabar Matriks | K16: Aljabar Matriks | L16: Belum dimulai | M16: Tinggi | N16: 45981 | O16: 45981 | Q16: 0 | S16: * | U16: *
A17: * | G17: * | H17: Akademik | I17: T&P, Kuliah | J17: PPT Akso | K17: Arsitektur Komputer dan Sistem Operasi | L17: Dalam proses | M17: Sedang | N17: 45965 | O17: 45972 | Q17: 0.7 | W17: *
H18: Akademik | I18: T&P, Praktikum | J18: Laporan Praktikum Pemdas | K18: Praktikum | L18: Belum dimulai | M18: Tinggi | N18: 45987 | O18: 46000 | Q18: 0 | X18: *
H19: Akademik | I19: T&P, Kuliah | J19: Projek Pemdas | K19: Pemograman Dasar | L19: Dalam proses | M19: Tinggi | N19: 45992 | O19: 46001 | Q19: 0.2 | T19: * | V19: *
H20: Non-Akademik | I20: JAR, Kuliah | J20: Minggu Tenang | K20: Lain-lain | L20: Belum dimulai | M20: Sedang | N20: 45999 | O20: 46005 | Q20: 0
H21: Akademik | I21: JAR, Kuliah | J21: UAS | K21: Lain-lain | L21: Belum dimulai | M21: Tinggi | N21: 46006 | O21: 46011 | Q21: 0
C22: * | H22: Non-Akademik | I22: JAR | J22: Libur Semester | K22: Lain-lain | L22: Belum dimulai | M22: Ringan | N22: 46013 | O22: 46075 | Q22: 0 | U22: * | X22: *
D23: * | E23: * | S23: * | W23: *
A24: * | C24: * | P24: * | T24: *
H25: * | Q25: * | V25: *
B26: * | F26: * | K26: * | R26: *
A27: * | D27: * | O27: * | U27: *
C28: * | N28: * | Q28: * | W28: *
E29: * | H29: * | O29: * | R29: * | T29: *
L30: * | V30: * | X30: *
J31: *

Sheet Database
A1: HOME | B1: DASHBOARD | C1: ENTRY DATA | D1: DATA BASE | E1: GRAPH | F1: JADWAL | G1: KALENDER | H1: TRACKER
T2: * | U2: *
F3: * | J3: * | W3: * | Y3: *
D4: * | H4: * | L4: *
AA5: *
B6: Semester | C6: Mata Kuliah | D6: Hari | E6: SKS | F6: Waktu | G6: Keterangan | H6: Kehadiran | I6: Progress | J6: Total Pertemuan | K6: Pertemuan Berjalan | M6: Semester | N6: Tanggal | O6: Mata Kuliah | P6: Status | R6: Semester | S6: Mata Kuliah | T6: Tugas 1 | U6: Quiz 1 | V6: UTS | W6: Tugas 2 | X6: Quiz 2 | Y6: UAS | Z6: Tugas akhir | AA6: Remedial
B7: 1 | C7: Literasi Digital | D7: Senin | E7: 3 | F7: 07.00-08.40 | G7: Online | H7: =LET( matkul, C7, berjalan, K7, jmlAbsen, COUNTIFS(O:O, matkul, P:P, "<>"), IF( berjalan = "", "", 1 - (jmlAbsen / berjalan) ) ) -> 0.92307692 | I7: =IF(K7="","", K7 / J7) -> 0.8125 | J7: 16 | K7: 13 | M7: 1 | N7: 45962 | O7: Literasi Digital | P7: Sakit | R7: 1 | S7: =C7 -> Literasi Digital | T7: 98 | U7: 89 | V7: 88 | W7: 96 | X7: 90 | Y7: 92 | Z7: 94 | AA7: -
B8: 1 | C8: Matematika Diskrit | D8: Senin | E8: 3 | F8: 09.30-12.00 | G8: E2.01.08 | H8: =LET( matkul, C8, berjalan, K8, jmlAbsen, COUNTIFS(O:O, matkul, P:P, "<>"), IF( berjalan = "", "", 1 - (jmlAbsen / berjalan) ) ) -> 1 | I8: =IF(K8="","", K8 / J8) -> 0.8125 | J8: 16 | K8: 13 | M8: 1 | N8: 45972 | O8: Pemograman Dasar | P8: Izin | R8: 1 | S8: =C8 -> Matematika Diskrit | T8: 96 | U8: 90 | V8: 91 | W8: 84 | X8: 92 | Y8: 94 | Z8: 88 | AA8: -
B9: 1 | C9: Pancasila | D9: Selasa | E9: 3 | F9: 10.20-12.00 | G9: Online | H9: =LET( matkul, C9, berjalan, K9, jmlAbsen, COUNTIFS(O:O, matkul, P:P, "<>"), IF( berjalan = "", "", 1 - (jmlAbsen / berjalan) ) ) -> 1 | I9: =IF(K9="","", K9 / J9) -> 0.8125 | J9: 16 | K9: 13 | M9: 1 | N9: 45970 | O9: Pemograman Dasar | P9: Sakit | R9: 1 | S9: =C9 -> Pancasila | T9: 97 | U9: 96 | V9: 90 | W9: 96 | X9: 93 | Y9: 85 | Z9: 98 | AA9: -
B10: 1 | C10: Pemograman Dasar | D10: Selasa | E10: 2 | F10: 13.00-15.30 | G10: E2.01.07 | H10: =LET( matkul, C10, berjalan, K10, jmlAbsen, COUNTIFS(O:O, matkul, P:P, "<>"), IF( berjalan = "", "", 1 - (jmlAbsen / berjalan) ) ) -> 0.84615385 | I10: =IF(K10="","", K10 / J10) -> 0.8125 | J10: 16 | K10: 13 | R10: 1 | S10: =C10 -> Pemograman Dasar | T10: 95 | U10: 98 | V10: 91 | W10: 93 | X10: 96 | Y10: 82 | Z10: 97 | AA10: -
B11: 1 | C11: Praktikum | D11: Rabu | E11: 2 | F11: 15.30-17.10 | G11: C1.04 | H11: =LET( matkul, C11, berjalan, K11, jmlAbsen, COUNTIFS(O:O, matkul, P:P, "<>"), IF( berjalan = "", "", 1 - (jmlAbsen / berjalan) ) ) -> 1 | I11: =IF(K11="","", K11 / J11) -> 0.8125 | J11: 16 | K11: 13 | R11: 1 | S11: =C11 -> Praktikum | T11: 88 | U11: - | V11: - | W11: 92 | X11: - | Y11: - | Z11: 96 | AA11: -
B12: 1 | C12: Arsitektur Komputer dan Sistem Operasi | D12: Kamis | E12: 3 | F12: 07.00-09.30 | G12: E2.01.08 | H12: =LET( matkul, C12, berjalan, K12, jmlAbsen, COUNTIFS(O:O, matkul, P:P, "<>"), IF( berjalan = "", "", 1 - (jmlAbsen / berjalan) ) ) -> 1 | I12: =IF(K12="","", K12 / J12) -> 0.8125 | J12: 16 | K12: 13 | R12: 1 | S12: =C12 -> Arsitektur Komputer dan Sistem Operasi | T12: 86 | U12: 74 | V12: 66 | W12: 88 | X12: 60 | Y12: 54 | Z12: 87 | AA12: 76
B13: 1 | C13: Aljabar Matriks | D13: Kamis | E13: 3 | F13: 09.30-12.00 | G13: E2.01.07 | H13: =LET( matkul, C13, berjalan, K13, jmlAbsen, COUNTIFS(O:O, matkul, P:P, "<>"), IF( berjalan = "", "", 1 - (jmlAbsen / berjalan) ) ) -> 1 | I13: =IF(K13="","", K13 / J13) -> 0.8125 | J13: 16 | K13: 13 | R13: 1 | S13: =C13 -> Aljabar Matriks | T13: 96 | U13: 88 | V13: 90 | W13: 94 | X13: 86 | Y13: 84 | Z13: 88 | AA13: -
B14: 1 | C14: Matematika Dasar | D14: Jumat | E14: 3 | F14: 13.00-15.30 | G14: E2.01.10 | H14: =LET( matkul, C14, berjalan, K14, jmlAbsen, COUNTIFS(O:O, matkul, P:P, "<>"), IF( berjalan = "", "", 1 - (jmlAbsen / berjalan) ) ) -> 1 | I14: =IF(K14="","", K14 / J14) -> 0.8125 | J14: 16 | K14: 13 | R14: 1 | S14: =C14 -> Matematika Dasar | T14: 92 | U14: 86 | V14: 90 | W14: 92 | X14: 90 | Y14: 92 | Z14: 95 | AA14: -
B15: 2 | C15: Kalkulus Lanjut | D15: Kamis | E15: 3 | H15: =LET( matkul, C15, berjalan, K15, jmlAbsen, COUNTIFS(O:O, matkul, P:P, "<>"), IF( berjalan = "", "", 1 - (jmlAbsen / berjalan) ) ) | I15: =IF(K15="","", K15 / J15) | R15: 2 | S15: =C15 -> Kalkulus Lanjut
B16: 2 | C16: Struktur Data dan Algoritma | E16: 3 | H16: =LET( matkul, C16, berjalan, K16, jmlAbsen, COUNTIFS(O:O, matkul, P:P, "<>"), IF( berjalan = "", "", 1 - (jmlAbsen / berjalan) ) ) | I16: =IF(K16="","", K16 / J16) | R16: 2 | S16: =C16 -> Struktur Data dan Algoritma
B17: 2 | C17: Pendidikan Kewarganegaraan | E17: 2 | H17: =LET( matkul, C17, berjalan, K17, jmlAbsen, COUNTIFS(O:O, matkul, P:P, "<>"), IF( berjalan = "", "", 1 - (jmlAbsen / berjalan) ) ) | I17: =IF(K17="","", K17 / J17) | R17: 2 | S17: =C17 -> Pendidikan Kewarganegaraan
B18: 2 | C18: Pendidikan Agama | E18: 2 | H18: =LET( matkul, C18, berjalan, K18, jmlAbsen, COUNTIFS(O:O, matkul, P:P, "<>"), IF( berjalan = "", "", 1 - (jmlAbsen / berjalan) ) ) | I18: =IF(K18="","", K18 / J18) | R18: 2 | S18: =C18 -> Pendidikan Agama
A19: * | B19: 2 | C19: Konservasi Sumber Daya Alam dan Lingkungan | E19: 2 | H19: =LET( matkul, C19, berjalan, K19, jmlAbsen, COUNTIFS(O:O, matkul, P:P, "<>"), IF( berjalan = "", "", 1 - (jmlAbsen / berjalan) ) ) | I19: =IF(K19="","", K19 / J19) | R19: 2 | S19: =C19 -> Konservasi Sumber Daya Alam dan Lingkungan
B20: 2 | C20: Teori Probabilitas | E20: 3 | H20: =LET( matkul, C20, berjalan, K20, jmlAbsen, COUNTIFS(O:O, matkul, P:P, "<>"), IF( berjalan = "", "", 1 - (jmlAbsen / berjalan) ) ) | I20: =IF(K20="","", K20 / J20) | R20: 2 | S20: =C20 -> Teori Probabilitas
B21: 2 | C21: Interaksi Manusia dan Komputer | E21: 3 | H21: =LET( matkul, C21, berjalan, K21, jmlAbsen, COUNTIFS(O:O, matkul, P:P, "<>"), IF( berjalan = "", "", 1 - (jmlAbsen / berjalan) ) ) | I21: =IF(K21="","", K21 / J21) | R21: 2 | S21: =C21 -> Interaksi Manusia dan Komputer
B22: 2 | C22: Etika Kecerdasan Artifisial | E22: 2 | H22: =LET( matkul, C22, berjalan, K22, jmlAbsen, COUNTIFS(O:O, matkul, P:P, "<>"), IF( berjalan = "", "", 1 - (jmlAbsen / berjalan) ) ) | I22: =IF(K22="","", K22 / J22) | R22: 2 | S22: =C22 -> Etika Kecerdasan Artifisial
B23: 3 | C23: Statistika Inferensial | E23: 3 | H23: =LET( matkul, C23, berjalan, K23, jmlAbsen, COUNTIFS(O:O, matkul, P:P, "<>"), IF( berjalan = "", "", 1 - (jmlAbsen / berjalan) ) ) | I23: =IF(K23="","", K23 / J23) | R23: 3 | S23: =C23 -> Statistika Inferensial
B24: 3 | C24: Kecerdasan Artifisial | E24: 3 | H24: =LET( matkul, C24, berjalan, K24, jmlAbsen, COUNTIFS(O:O, matkul, P:P, "<>"), IF( berjalan = "", "", 1 - (jmlAbsen / berjalan) ) ) | I24: =IF(K24="","", K24 / J24) | R24: 3 | S24: =C24 -> Kecerdasan Artifisial
B25: 3 | C25: Keamanan dan Integritas Data | E25: 3 | H25: =LET( matkul, C25, berjalan, K25, jmlAbsen, COUNTIFS(O:O, matkul, P:P, "<>"), IF( berjalan = "", "", 1 - (jmlAbsen / berjalan) ) ) | I25: =IF(K25="","", K25 / J25) | R25: 3 | S25: =C25 -> Keamanan dan Integritas Data
B26: 3 | C26: Pemrosesan Teks | E26: 3 | H26: =LET( matkul, C26, berjalan, K26, jmlAbsen, COUNTIFS(O:O, matkul, P:P, "<>"), IF( berjalan = "", "", 1 - (jmlAbsen / berjalan) ) ) | I26: =IF(K26="","", K26 / J26) | R26: 3 | S26: =C26 -> Pemrosesan Teks
B27: 3 | C27: Basis Data | E27: 3 | H27: =LET( matkul, C27, berjalan, K27, jmlAbsen, COUNTIFS(O:O, matkul, P:P, "<>"), IF( berjalan = "", "", 1 - (jmlAbsen / berjalan) ) ) | I27: =IF(K27="","", K27 / J27) | R27: 3 | S27: =C27 -> Basis Data
B28: 3 | C28: Desain dan Analisis Algoritma | E28: 3 | H28: =LET( matkul, C28, berjalan, K28, jmlAbsen, COUNTIFS(O:O, matkul, P:P, "<>"), IF( berjalan = "", "", 1 - (jmlAbsen / berjalan) ) ) | I28: =IF(K28="","", K28 / J28) | R28: 3 | S28: =C28 -> Desain dan Analisis Algoritma
B29: 3 | C29: Pengolahan Sinyal Digital | E29: 2 | H29: =LET( matkul, C29, berjalan, K29, jmlAbsen, COUNTIFS(O:O, matkul, P:P, "<>"), IF( berjalan = "", "", 1 - (jmlAbsen / berjalan) ) ) | I29: =IF(K29="","", K29 / J29) | R29: 3 | S29: =C29 -> Pengolahan Sinyal Digital
B30: 3 | C30: Bahasa Indonesia | E30: 2 | H30: =LET( matkul, C30, berjalan, K30, jmlAbsen, COUNTIFS(O:O, matkul, P:P, "<>"), IF( berjalan = "", "", 1 - (jmlAbsen / berjalan) ) ) | I30: =IF(K30="","", K30 / J30) | R30: 3 | S30: =C30 -> Bahasa Indonesia
B31: 4 | C31: Penambangan Data | E31: 3 | H31: =LET( matkul, C31, berjalan, K31, jmlAbsen, COUNTIFS(O:O, matkul, P:P, "<>"), IF( berjalan = "", "", 1 - (jmlAbsen / berjalan) ) ) | I31: =IF(K31="","", K31 / J31) | R31: 4 | S31: =C31 -> Penambangan Data
... B60: 8 | C60: Tugas Akhir | E60: 4 | H60: =LET( matkul, C60, berjalan, K60, jmlAbsen, COUNTIFS(O:O, matkul, P:P, "<>"), IF( berjalan = "", "", 1 - (jmlAbsen / berjalan) ) ) | I60: =IF(K60="","", K60 / J60) | R60: 8 | S60: =C60 -> Tugas Akhir
P66: *

Sheet Graph
A1: HOME | B1: DASHBOARD | C1: ENTRY DATA | D1: DATA BASE | E1: GRAPH | F1: JADWAL | G1: KALENDER | H1: TRACKER | R1: *
H2: * | W2: * | AB2: *
C3: * | I3: * | O3: * | V3: *
B4: * | D4: * | G4: * | Y4: *
L5: * | R5: *
W6: * | AA6: *
A7: * | F7: *
B11: * | J11: * | K11: * | M11: * | R11: * | S11: *
H13: Mata Kuliah | I13: Semester | J13: Kehadiran | K13: Progress | L13: * | P13: * | V13: *
A14: * | H14: =IFERROR(__xludf.DUMMYFUNCTION("FILTER( {Database!C7:C624,Database!B7:B624,Database!H7:H624,Database!I7:I624}, Database!C7:C624<>"""" ) "),"Literasi Digital") -> Literasi Digital | I14: =IFERROR(__xludf.DUMMYFUNCTION("""COMPUTED_VALUE"""),1.0) -> 1 | J14: =IFERROR(__xludf.DUMMYFUNCTION("""COMPUTED_VALUE"""),0.9230769230769231) -> 0.92307692 | K14: =IFERROR(__xludf.DUMMYFUNCTION("""COMPUTED_VALUE"""),0.8125) -> 0.8125
H15: =IFERROR(__xludf.DUMMYFUNCTION("""COMPUTED_VALUE"""),"Matematika Diskrit") -> Matematika Diskrit | I15: =IFERROR(__xludf.DUMMYFUNCTION("""COMPUTED_VALUE"""),1.0) -> 1 | J15: =IFERROR(__xludf.DUMMYFUNCTION("""COMPUTED_VALUE"""),1.0) -> 1 | K15: =IFERROR(__xludf.DUMMYFUNCTION("""COMPUTED_VALUE"""),0.8125) -> 0.8125
H16: =IFERROR(__xludf.DUMMYFUNCTION("""COMPUTED_VALUE"""),"Pancasila") -> Pancasila | I16: =IFERROR(__xludf.DUMMYFUNCTION("""COMPUTED_VALUE"""),1.0) -> 1 | J16: =IFERROR(__xludf.DUMMYFUNCTION("""COMPUTED_VALUE"""),1.0) -> 1 | K16: =IFERROR(__xludf.DUMMYFUNCTION("""COMPUTED_VALUE"""),0.8125) -> 0.8125
H17: =IFERROR(__xludf.DUMMYFUNCTION("""COMPUTED_VALUE"""),"Pemograman Dasar") -> Pemograman Dasar | I17: =IFERROR(__xludf.DUMMYFUNCTION("""COMPUTED_VALUE"""),1.0) -> 1 | J17: =IFERROR(__xludf.DUMMYFUNCTION("""COMPUTED_VALUE"""),0.8461538461538461) -> 0.84615385 | K17: =IFERROR(__xludf.DUMMYFUNCTION("""COMPUTED_VALUE"""),0.8125) -> 0.8125
H18: =IFERROR(__xludf.DUMMYFUNCTION("""COMPUTED_VALUE"""),"Praktikum") -> Praktikum | I18: =IFERROR(__xludf.DUMMYFUNCTION("""COMPUTED_VALUE"""),1.0) -> 1 | J18: =IFERROR(__xludf.DUMMYFUNCTION("""COMPUTED_VALUE"""),1.0) -> 1 | K18: =IFERROR(__xludf.DUMMYFUNCTION("""COMPUTED_VALUE"""),0.8125) -> 0.8125
B19: * | H19: =IFERROR(__xludf.DUMMYFUNCTION("""COMPUTED_VALUE"""),"Arsitektur Komputer dan Sistem Operasi") -> Arsitektur Komputer dan Sistem Operasi | I19: =IFERROR(__xludf.DUMMYFUNCTION("""COMPUTED_VALUE"""),1.0) -> 1 | J19: =IFERROR(__xludf.DUMMYFUNCTION("""COMPUTED_VALUE"""),1.0) -> 1 | K19: =IFERROR(__xludf.DUMMYFUNCTION("""COMPUTED_VALUE"""),0.8125) -> 0.8125
H20: =IFERROR(__xludf.DUMMYFUNCTION("""COMPUTED_VALUE"""),"Aljabar Matriks") -> Aljabar Matriks | I20: =IFERROR(__xludf.DUMMYFUNCTION("""COMPUTED_VALUE"""),1.0) -> 1 | J20: =IFERROR(__xludf.DUMMYFUNCTION("""COMPUTED_VALUE"""),1.0) -> 1 | K20: =IFERROR(__xludf.DUMMYFUNCTION("""COMPUTED_VALUE"""),0.8125) -> 0.8125
B21: * | H21: =IFERROR(__xludf.DUMMYFUNCTION("""COMPUTED_VALUE"""),"Matematika Dasar") -> Matematika Dasar | I21: =IFERROR(__xludf.DUMMYFUNCTION("""COMPUTED_VALUE"""),1.0) -> 1 | J21: =IFERROR(__xludf.DUMMYFUNCTION("""COMPUTED_VALUE"""),1.0) -> 1 | K21: =IFERROR(__xludf.DUMMYFUNCTION("""COMPUTED_VALUE"""),0.8125) -> 0.8125
H22: =IFERROR(__xludf.DUMMYFUNCTION("""COMPUTED_VALUE"""),"Kalkulus Lanjut") -> Kalkulus Lanjut | I22: =IFERROR(__xludf.DUMMYFUNCTION("""COMPUTED_VALUE"""),2.0) -> 2 | J22: =IFERROR(__xludf.DUMMYFUNCTION("""COMPUTED_VALUE"""),"") | K22: =IFERROR(__xludf.DUMMYFUNCTION("""COMPUTED_VALUE"""),"")
B23: * | C23: * | D23: * | F23: * | H23: =IFERROR(__xludf.DUMMYFUNCTION("""COMPUTED_VALUE"""),"Struktur Data dan Algoritma") -> Struktur Data dan Algoritma | I23: =IFERROR(__xludf.DUMMYFUNCTION("""COMPUTED_VALUE"""),2.0) -> 2 | J23: =IFERROR(__xludf.DUMMYFUNCTION("""COMPUTED_VALUE"""),"") | K23: =IFERROR(__xludf.DUMMYFUNCTION("""COMPUTED_VALUE"""),"")
H24: =IFERROR(__xludf.DUMMYFUNCTION("""COMPUTED_VALUE"""),"Pendidikan Kewarganegaraan") -> Pendidikan Kewarganegaraan | I24: =IFERROR(__xludf.DUMMYFUNCTION("""COMPUTED_VALUE"""),2.0) -> 2 | J24: =IFERROR(__xludf.DUMMYFUNCTION("""COMPUTED_VALUE"""),"") | K24: =IFERROR(__xludf.DUMMYFUNCTION("""COMPUTED_VALUE"""),"")
D25: * | H25: =IFERROR(__xludf.DUMMYFUNCTION("""COMPUTED_VALUE"""),"Pendidikan Agama") -> Pendidikan Agama | I25: =IFERROR(__xludf.DUMMYFUNCTION("""COMPUTED_VALUE"""),2.0) -> 2 | J25: =IFERROR(__xludf.DUMMYFUNCTION("""COMPUTED_VALUE"""),"") | K25: =IFERROR(__xludf.DUMMYFUNCTION("""COMPUTED_VALUE"""),"")
B26: * | C26: * | H26: =IFERROR(__xludf.DUMMYFUNCTION("""COMPUTED_VALUE"""),"Konservasi Sumber Daya Alam dan Lingkungan") -> Konservasi Sumber Daya Alam dan Lingkungan | I26: =IFERROR(__xludf.DUMMYFUNCTION("""COMPUTED_VALUE"""),2.0) -> 2 | J26: =IFERROR(__xludf.DUMMYFUNCTION("""COMPUTED_VALUE"""),"") | K26: =IFERROR(__xludf.DUMMYFUNCTION("""COMPUTED_VALUE"""),"")
E27: * | H27: =IFERROR(__xludf.DUMMYFUNCTION("""COMPUTED_VALUE"""),"Teori Probabilitas") -> Teori Probabilitas | I27: =IFERROR(__xludf.DUMMYFUNCTION("""COMPUTED_VALUE"""),2.0) -> 2 | J27: =IFERROR(__xludf.DUMMYFUNCTION("""COMPUTED_VALUE"""),"") | K27: =IFERROR(__xludf.DUMMYFUNCTION("""COMPUTED_VALUE"""),"")
A28: * | H28: =IFERROR(__xludf.DUMMYFUNCTION("""COMPUTED_VALUE"""),"Interaksi Manusia dan Komputer") -> Interaksi Manusia dan Komputer | I28: =IFERROR(__xludf.DUMMYFUNCTION("""COMPUTED_VALUE"""),2.0) -> 2 | J28: =IFERROR(__xludf.DUMMYFUNCTION("""COMPUTED_VALUE"""),"") | K28: =IFERROR(__xludf.DUMMYFUNCTION("""COMPUTED_VALUE"""),"")
H29: =IFERROR(__xludf.DUMMYFUNCTION("""COMPUTED_VALUE"""),"Etika Kecerdasan Artifisial") -> Etika Kecerdasan Artifisial | I29: =IFERROR(__xludf.DUMMYFUNCTION("""COMPUTED_VALUE"""),2.0) -> 2 | J29: =IFERROR(__xludf.DUMMYFUNCTION("""COMPUTED_VALUE"""),"") | K29: =IFERROR(__xludf.DUMMYFUNCTION("""COMPUTED_VALUE"""),"")
H30: =IFERROR(__xludf.DUMMYFUNCTION("""COMPUTED_VALUE"""),"Statistika Inferensial") -> Statistika Inferensial | I30: =IFERROR(__xludf.DUMMYFUNCTION("""COMPUTED_VALUE"""),3.0) -> 3 | J30: =IFERROR(__xludf.DUMMYFUNCTION("""COMPUTED_VALUE"""),"") | K30: =IFERROR(__xludf.DUMMYFUNCTION("""COMPUTED_VALUE"""),"")
H31: =IFERROR(__xludf.DUMMYFUNCTION("""COMPUTED_VALUE"""),"Kecerdasan Artifisial") -> Kecerdasan Artifisial | I31: =IFERROR(__xludf.DUMMYFUNCTION("""COMPUTED_VALUE"""),3.0) -> 3 | J31: =IFERROR(__xludf.DUMMYFUNCTION("""COMPUTED_VALUE"""),"") | K31: =IFERROR(__xludf.DUMMYFUNCTION("""COMPUTED_VALUE"""),"")
H32: =IFERROR(__xludf.DUMMYFUNCTION("""COMPUTED_VALUE"""),"Keamanan dan Integritas Data") -> Keamanan dan Integritas Data | I32: =IFERROR(__xludf.DUMMYFUNCTION("""COMPUTED_VALUE"""),3.0) -> 3 | J32: =IFERROR(__xludf.DUMMYFUNCTION("""COMPUTED_VALUE"""),"") | K32: =IFERROR(__xludf.DUMMYFUNCTION("""COMPUTED_VALUE"""),"")
H33: =IFERROR(__xludf.DUMMYFUNCTION("""COMPUTED_VALUE"""),"Pemrosesan Teks") -> Pemrosesan Teks | I33: =IFERROR(__xludf.DUMMYFUNCTION("""COMPUTED_VALUE"""),3.0) -> 3 | J33: =IFERROR(__xludf.DUMMYFUNCTION("""COMPUTED_VALUE"""),"") | K33: =IFERROR(__xludf.DUMMYFUNCTION("""COMPUTED_VALUE"""),"")
H34: =IFERROR(__xludf.DUMMYFUNCTION("""COMPUTED_VALUE"""),"Basis Data") -> Basis Data | I34: =IFERROR(__xludf.DUMMYFUNCTION("""COMPUTED_VALUE"""),3.0) -> 3 | J34: =IFERROR(__xludf.DUMMYFUNCTION("""COMPUTED_VALUE"""),"") | K34: =IFERROR(__xludf.DUMMYFUNCTION("""COMPUTED_VALUE"""),"")
A35: * | H35: =IFERROR(__xludf.DUMMYFUNCTION("""COMPUTED_VALUE"""),"Desain dan Analisis Algoritma") -> Desain dan Analisis Algoritma | I35: =IFERROR(__xludf.DUMMYFUNCTION("""COMPUTED_VALUE"""),3.0) -> 3 | J35: =IFERROR(__xludf.DUMMYFUNCTION("""COMPUTED_VALUE"""),"") | K35: =IFERROR(__xludf.DUMMYFUNCTION("""COMPUTED_VALUE"""),"")
H36: =IFERROR(__xludf.DUMMYFUNCTION("""COMPUTED_VALUE"""),"Pengolahan Sinyal Digital") -> Pengolahan Sinyal Digital | I36: =IFERROR(__xludf.DUMMYFUNCTION("""COMPUTED_VALUE"""),3.0) -> 3 | J36: =IFERROR(__xludf.DUMMYFUNCTION("""COMPUTED_VALUE"""),"") | K36: =IFERROR(__xludf.DUMMYFUNCTION("""COMPUTED_VALUE"""),"")
H37: =IFERROR(__xludf.DUMMYFUNCTION("""COMPUTED_VALUE"""),"Bahasa Indonesia") -> Bahasa Indonesia | I37: =IFERROR(__xludf.DUMMYFUNCTION("""COMPUTED_VALUE"""),3.0) -> 3 | J37: =IFERROR(__xludf.DUMMYFUNCTION("""COMPUTED_VALUE"""),"") | K37: =IFERROR(__xludf.DUMMYFUNCTION("""COMPUTED_VALUE"""),"")
H38: =IFERROR(__xludf.DUMMYFUNCTION("""COMPUTED_VALUE"""),"Penambangan Data") -> Penambangan Data | I38: =IFERROR(__xludf.DUMMYFUNCTION("""COMPUTED_VALUE"""),4.0) -> 4 | J38: =IFERROR(__xludf.DUMMYFUNCTION("""COMPUTED_VALUE"""),"") | K38: =IFERROR(__xludf.DUMMYFUNCTION("""COMPUTED_VALUE"""),"")
A39: * | H39: =IFERROR(__xludf.DUMMYFUNCTION("""COMPUTED_VALUE"""),"Data Warehouse dan Komputasi Terdistribusi") -> Data Warehouse dan Komputasi Terdistribusi | I39: =IFERROR(__xludf.DUMMYFUNCTION("""COMPUTED_VALUE"""),4.0) -> 4 | J39: =IFERROR(__xludf.DUMMYFUNCTION("""COMPUTED_VALUE"""),"") | K39: =IFERROR(__xludf.DUMMYFUNCTION("""COMPUTED_VALUE"""),"")
H40: =IFERROR(__xludf.DUMMYFUNCTION("""COMPUTED_VALUE"""),"Pengolahan Citra Digital") -> Pengolahan Citra Digital | I40: =IFERROR(__xludf.DUMMYFUNCTION("""COMPUTED_VALUE"""),4.0) -> 4 | J40: =IFERROR(__xludf.DUMMYFUNCTION("""COMPUTED_VALUE"""),"") | K40: =IFERROR(__xludf.DUMMYFUNCTION("""COMPUTED_VALUE"""),"")
H41: =IFERROR(__xludf.DUMMYFUNCTION("""COMPUTED_VALUE"""),"Analisis Multivariat") -> Analisis Multivariat | I41: =IFERROR(__xludf.DUMMYFUNCTION("""COMPUTED_VALUE"""),4.0) -> 4 | J41: =IFERROR(__xludf.DUMMYFUNCTION("""COMPUTED_VALUE"""),"") | K41: =IFERROR(__xludf.DUMMYFUNCTION("""COMPUTED_VALUE"""),"")
H42: =IFERROR(__xludf.DUMMYFUNCTION("""COMPUTED_VALUE"""),"Pembelajaran Mesin Dasar") -> Pembelajaran Mesin Dasar | I42: =IFERROR(__xludf.DUMMYFUNCTION("""COMPUTED_VALUE"""),4.0) -> 4 | J42: =IFERROR(__xludf.DUMMYFUNCTION("""COMPUTED_VALUE"""),"") | K42: =IFERROR(__xludf.DUMMYFUNCTION("""COMPUTED_VALUE"""),"")
H43: =IFERROR(__xludf.DUMMYFUNCTION("""COMPUTED_VALUE"""),"Rekayasa Perangkat Lunak") -> Rekayasa Perangkat Lunak | I43: =IFERROR(__xludf.DUMMYFUNCTION("""COMPUTED_VALUE"""),4.0) -> 4 | J43: =IFERROR(__xludf.DUMMYFUNCTION("""COMPUTED_VALUE"""),"") | K43: =IFERROR(__xludf.DUMMYFUNCTION("""COMPUTED_VALUE"""),"")
H44: =IFERROR(__xludf.DUMMYFUNCTION("""COMPUTED_VALUE"""),"Pendidikan Jasmani dan Kebugaran") -> Pendidikan Jasmani dan Kebugaran | I44: =IFERROR(__xludf.DUMMYFUNCTION("""COMPUTED_VALUE"""),4.0) -> 4 | J44: =IFERROR(__xludf.DUMMYFUNCTION("""COMPUTED_VALUE"""),"") | K44: =IFERROR(__xludf.DUMMYFUNCTION("""COMPUTED_VALUE"""),"")
...

Sheet Jadwal Kuliah
A1: HOME | B1: DASHBOARD | C1: ENTRY DATA | D1: DATA BASE | E1: GRAPH | F1: JADWAL | G1: KALENDER | H1: TRACKER | V1: *
B2: *
L3: * | R3: * | X3: *
B6: Mata Kuliah | C6: Hari | D6: SKS | E6: Waktu | F6: Keterangan | G6: Kehadiran | H6: Progress | J6: Mata Kuliah | K6: Hari | L6: SKS | M6: Waktu | N6: Keterangan | O6: Kehadiran | P6: Progress | R6: Mata Kuliah | S6: Hari | T6: SKS | U6: Waktu | V6: Keterangan | W6: Kehadiran | X6: Progress
B7: =IFERROR(__xludf.DUMMYFUNCTION("QUERY(Database!B7:J58, ""select C, D, E, F, G, H, I where B = 1"", 0) "),"Literasi Digital") -> Literasi Digital | C7: =IFERROR(__xludf.DUMMYFUNCTION("""COMPUTED_VALUE"""),"Senin") -> Senin | D7: =IFERROR(__xludf.DUMMYFUNCTION("""COMPUTED_VALUE"""),3.0) -> 3 | E7: =IFERROR(__xludf.DUMMYFUNCTION("""COMPUTED_VALUE"""),"07.00-08.40") -> 07.00-08.40 | F7: =IFERROR(__xludf.DUMMYFUNCTION("""COMPUTED_VALUE"""),"Online") -> Online | G7: =IFERROR(__xludf.DUMMYFUNCTION("""COMPUTED_VALUE"""),0.9230769230769231) -> 0.92307692 | H7: =IFERROR(__xludf.DUMMYFUNCTION("""COMPUTED_VALUE"""),0.8125) -> 0.8125 | J7: =IFERROR(__xludf.DUMMYFUNCTION("QUERY(Database!B7:J58, ""select C, D, E, F, G, H, I where B = 2"", 0) "),"Kalkulus Lanjut") -> Kalkulus Lanjut | K7: =IFERROR(__xludf.DUMMYFUNCTION("""COMPUTED_VALUE"""),"Kamis") -> Kamis | L7: =IFERROR(__xludf.DUMMYFUNCTION("""COMPUTED_VALUE"""),3.0) -> 3 | R7: =IFERROR(__xludf.DUMMYFUNCTION("QUERY(Database!B7:J58, ""select C, D, E, F, G, H, I where B = 3"", 0) "),"Statistika Inferensial") -> Statistika Inferensial | T7: =IFERROR(__xludf.DUMMYFUNCTION("""COMPUTED_VALUE"""),3.0) -> 3
B8: =IFERROR(__xludf.DUMMYFUNCTION("""COMPUTED_VALUE"""),"Matematika Diskrit") -> Matematika Diskrit | C8: =IFERROR(__xludf.DUMMYFUNCTION("""COMPUTED_VALUE"""),"Senin") -> Senin | D8: =IFERROR(__xludf.DUMMYFUNCTION("""COMPUTED_VALUE"""),3.0) -> 3 | E8: =IFERROR(__xludf.DUMMYFUNCTION("""COMPUTED_VALUE"""),"09.30-12.00") -> 09.30-12.00 | F8: =IFERROR(__xludf.DUMMYFUNCTION("""COMPUTED_VALUE"""),"E2.01.08") -> E2.01.08 | G8: =IFERROR(__xludf.DUMMYFUNCTION("""COMPUTED_VALUE"""),1.0) -> 1 | H8: =IFERROR(__xludf.DUMMYFUNCTION("""COMPUTED_VALUE"""),0.8125) -> 0.8125 | J8: =IFERROR(__xludf.DUMMYFUNCTION("""COMPUTED_VALUE"""),"Struktur Data dan Algoritma") -> Struktur Data dan Algoritma | L8: =IFERROR(__xludf.DUMMYFUNCTION("""COMPUTED_VALUE"""),3.0) -> 3 | R8: =IFERROR(__xludf.DUMMYFUNCTION("""COMPUTED_VALUE"""),"Kecerdasan Artifisial") -> Kecerdasan Artifisial | T8: =IFERROR(__xludf.DUMMYFUNCTION("""COMPUTED_VALUE"""),3.0) -> 3
B9: =IFERROR(__xludf.DUMMYFUNCTION("""COMPUTED_VALUE"""),"Pancasila") -> Pancasila | C9: =IFERROR(__xludf.DUMMYFUNCTION("""COMPUTED_VALUE"""),"Selasa") -> Selasa | D9: =IFERROR(__xludf.DUMMYFUNCTION("""COMPUTED_VALUE"""),3.0) -> 3 | E9: =IFERROR(__xludf.DUMMYFUNCTION("""COMPUTED_VALUE"""),"10.20-12.00") -> 10.20-12.00 | F9: =IFERROR(__xludf.DUMMYFUNCTION("""COMPUTED_VALUE"""),"Online") -> Online | G9: =IFERROR(__xludf.DUMMYFUNCTION("""COMPUTED_VALUE"""),1.0) -> 1 | H9: =IFERROR(__xludf.DUMMYFUNCTION("""COMPUTED_VALUE"""),0.8125) -> 0.8125 | J9: =IFERROR(__xludf.DUMMYFUNCTION("""COMPUTED_VALUE"""),"Pendidikan Kewarganegaraan") -> Pendidikan Kewarganegaraan | L9: =IFERROR(__xludf.DUMMYFUNCTION("""COMPUTED_VALUE"""),2.0) -> 2 | R9: =IFERROR(__xludf.DUMMYFUNCTION("""COMPUTED_VALUE"""),"Keamanan dan Integritas Data") -> Keamanan dan Integritas Data | T9: =IFERROR(__xludf.DUMMYFUNCTION("""COMPUTED_VALUE"""),3.0) -> 3
A10: * | B10: =IFERROR(__xludf.DUMMYFUNCTION("""COMPUTED_VALUE"""),"Pemograman Dasar") -> Pemograman Dasar | C10: =IFERROR(__xludf.DUMMYFUNCTION("""COMPUTED_VALUE"""),"Selasa") -> Selasa | D10: =IFERROR(__xludf.DUMMYFUNCTION("""COMPUTED_VALUE"""),2.0) -> 2 | E10: =IFERROR(__xludf.DUMMYFUNCTION("""COMPUTED_VALUE"""),"13.00-15.30") -> 13.00-15.30 | F10: =IFERROR(__xludf.DUMMYFUNCTION("""COMPUTED_VALUE"""),"E2.01.07") -> E2.01.07 | G10: =IFERROR(__xludf.DUMMYFUNCTION("""COMPUTED_VALUE"""),0.8461538461538461) -> 0.84615385 | H10: =IFERROR(__xludf.DUMMYFUNCTION("""COMPUTED_VALUE"""),0.8125) -> 0.8125 | J10: =IFERROR(__xludf.DUMMYFUNCTION("""COMPUTED_VALUE"""),"Pendidikan Agama") -> Pendidikan Agama | L10: =IFERROR(__xludf.DUMMYFUNCTION("""COMPUTED_VALUE"""),2.0) -> 2 | R10: =IFERROR(__xludf.DUMMYFUNCTION("""COMPUTED_VALUE"""),"Pemrosesan Teks") -> Pemrosesan Teks | T10: =IFERROR(__xludf.DUMMYFUNCTION("""COMPUTED_VALUE"""),3.0) -> 3
B11: =IFERROR(__xludf.DUMMYFUNCTION("""COMPUTED_VALUE"""),"Praktikum") -> Praktikum | C11: =IFERROR(__xludf.DUMMYFUNCTION("""COMPUTED_VALUE"""),"Rabu") -> Rabu | D11: =IFERROR(__xludf.DUMMYFUNCTION("""COMPUTED_VALUE"""),2.0) -> 2 | E11: =IFERROR(__xludf.DUMMYFUNCTION("""COMPUTED_VALUE"""),"15.30-17.10") -> 15.30-17.10 | F11: =IFERROR(__xludf.DUMMYFUNCTION("""COMPUTED_VALUE"""),"C1.04") -> C1.04 | G11: =IFERROR(__xludf.DUMMYFUNCTION("""COMPUTED_VALUE"""),1.0) -> 1 | H11: =IFERROR(__xludf.DUMMYFUNCTION("""COMPUTED_VALUE"""),0.8125) -> 0.8125 | J11: =IFERROR(__xludf.DUMMYFUNCTION("""COMPUTED_VALUE"""),"Konservasi Sumber Daya Alam dan Lingkungan") -> Konservasi Sumber Daya Alam dan Lingkungan | L11: =IFERROR(__xludf.DUMMYFUNCTION("""COMPUTED_VALUE"""),2.0) -> 2 | Q11: * | R11: =IFERROR(__xludf.DUMMYFUNCTION("""COMPUTED_VALUE"""),"Basis Data") -> Basis Data | T11: =IFERROR(__xludf.DUMMYFUNCTION("""COMPUTED_VALUE"""),3.0) -> 3
B12: =IFERROR(__xludf.DUMMYFUNCTION("""COMPUTED_VALUE"""),"Arsitektur Komputer dan Sistem Operasi") -> Arsitektur Komputer dan Sistem Operasi | C12: =IFERROR(__xludf.DUMMYFUNCTION("""COMPUTED_VALUE"""),"Kamis") -> Kamis | D12: =IFERROR(__xludf.DUMMYFUNCTION("""COMPUTED_VALUE"""),3.0) -> 3 | E12: =IFERROR(__xludf.DUMMYFUNCTION("""COMPUTED_VALUE"""),"07.00-09.30") -> 07.00-09.30 | F12: =IFERROR(__xludf.DUMMYFUNCTION("""COMPUTED_VALUE"""),"E2.01.08") -> E2.01.08 | G12: =IFERROR(__xludf.DUMMYFUNCTION("""COMPUTED_VALUE"""),1.0) -> 1 | H12: =IFERROR(__xludf.DUMMYFUNCTION("""COMPUTED_VALUE"""),0.8125) -> 0.8125 | J12: =IFERROR(__xludf.DUMMYFUNCTION("""COMPUTED_VALUE"""),"Teori Probabilitas") -> Teori Probabilitas | L12: =IFERROR(__xludf.DUMMYFUNCTION("""COMPUTED_VALUE"""),3.0) -> 3 | R12: =IFERROR(__xludf.DUMMYFUNCTION("""COMPUTED_VALUE"""),"Desain dan Analisis Algoritma") -> Desain dan Analisis Algoritma | T12: =IFERROR(__xludf.DUMMYFUNCTION("""COMPUTED_VALUE"""),3.0) -> 3
B13: =IFERROR(__xludf.DUMMYFUNCTION("""COMPUTED_VALUE"""),"Aljabar Matriks") -> Aljabar Matriks | C13: =IFERROR(__xludf.DUMMYFUNCTION("""COMPUTED_VALUE"""),"Kamis") -> Kamis | D13: =IFERROR(__xludf.DUMMYFUNCTION("""COMPUTED_VALUE"""),3.0) -> 3 | E13: =IFERROR(__xludf.DUMMYFUNCTION("""COMPUTED_VALUE"""),"09.30-12.00") -> 09.30-12.00 | F13: =IFERROR(__xludf.DUMMYFUNCTION("""COMPUTED_VALUE"""),"E2.01.07") -> E2.01.07 | G13: =IFERROR(__xludf.DUMMYFUNCTION("""COMPUTED_VALUE"""),1.0) -> 1 | H13: =IFERROR(__xludf.DUMMYFUNCTION("""COMPUTED_VALUE"""),0.8125) -> 0.8125 | J13: =IFERROR(__xludf.DUMMYFUNCTION("""COMPUTED_VALUE"""),"Interaksi Manusia dan Komputer") -> Interaksi Manusia dan Komputer | L13: =IFERROR(__xludf.DUMMYFUNCTION("""COMPUTED_VALUE"""),3.0) -> 3 | R13: =IFERROR(__xludf.DUMMYFUNCTION("""COMPUTED_VALUE"""),"Pengolahan Sinyal Digital") -> Pengolahan Sinyal Digital | T13: =IFERROR(__xludf.DUMMYFUNCTION("""COMPUTED_VALUE"""),2.0) -> 2
B14: =IFERROR(__xludf.DUMMYFUNCTION("""COMPUTED_VALUE"""),"Matematika Dasar") -> Matematika Dasar | C14: =IFERROR(__xludf.DUMMYFUNCTION("""COMPUTED_VALUE"""),"Jumat") -> Jumat | D14: =IFERROR(__xludf.DUMMYFUNCTION("""COMPUTED_VALUE"""),3.0) -> 3 | E14: =IFERROR(__xludf.DUMMYFUNCTION("""COMPUTED_VALUE"""),"13.00-15.30") -> 13.00-15.30 | F14: =IFERROR(__xludf.DUMMYFUNCTION("""COMPUTED_VALUE"""),"E2.01.10") -> E2.01.10 | G14: =IFERROR(__xludf.DUMMYFUNCTION("""COMPUTED_VALUE"""),1.0) -> 1 | H14: =IFERROR(__xludf.DUMMYFUNCTION("""COMPUTED_VALUE"""),0.8125) -> 0.8125 | J14: =IFERROR(__xludf.DUMMYFUNCTION("""COMPUTED_VALUE"""),"Etika Kecerdasan Artifisial") -> Etika Kecerdasan Artifisial | L14: =IFERROR(__xludf.DUMMYFUNCTION("""COMPUTED_VALUE"""),2.0) -> 2 | R14: =IFERROR(__xludf.DUMMYFUNCTION("""COMPUTED_VALUE"""),"Bahasa Indonesia") -> Bahasa Indonesia | T14: =IFERROR(__xludf.DUMMYFUNCTION("""COMPUTED_VALUE"""),2.0) -> 2
W15: *
I16: * | Y16: *
B17: Mata Kuliah | C17: Hari | D17: SKS | E17: Waktu | F17: Keterangan | G17: Kehadiran | H17: Progress | J17: Mata Kuliah | K17: Hari | L17: SKS | M17: Waktu | N17: Keterangan | O17: Kehadiran | P17: Progress | R17: Mata Kuliah | S17: Hari | T17: SKS | U17: Waktu | V17: Keterangan | W17: Kehadiran | X17: Progress
B18: =IFERROR(__xludf.DUMMYFUNCTION("QUERY(Database!B7:J58, ""select C, D, E, F, G, H, I where B = 4"", 0) "),"Penambangan Data") -> Penambangan Data | D18: =IFERROR(__xludf.DUMMYFUNCTION("""COMPUTED_VALUE"""),3.0) -> 3 | J18: =IFERROR(__xludf.DUMMYFUNCTION("QUERY(Database!B7:J58, ""select C, D, E, F, G, H, I where B = 5"", 0) "),"Tata Tulis Ilmiah") -> Tata Tulis Ilmiah | L18: =IFERROR(__xludf.DUMMYFUNCTION("""COMPUTED_VALUE"""),2.0) -> 2 | R18: =IFERROR(__xludf.DUMMYFUNCTION("QUERY(Database!B7:J58, ""select C, D, E, F, G, H, I where B = 6"", 0) "),"Manajemen Risiko") -> Manajemen Risiko | T18: =IFERROR(__xludf.DUMMYFUNCTION("""COMPUTED_VALUE"""),3.0) -> 3
B19: =IFERROR(__xludf.DUMMYFUNCTION("""COMPUTED_VALUE"""),"Data Warehouse dan Komputasi Terdistribusi") -> Data Warehouse dan Komputasi Terdistribusi | D19: =IFERROR(__xludf.DUMMYFUNCTION("""COMPUTED_VALUE"""),3.0) -> 3 | J19: =IFERROR(__xludf.DUMMYFUNCTION("""COMPUTED_VALUE"""),"Komunikasi Publik") -> Komunikasi Publik | L19: =IFERROR(__xludf.DUMMYFUNCTION("""COMPUTED_VALUE"""),2.0) -> 2 | R19: =IFERROR(__xludf.DUMMYFUNCTION("""COMPUTED_VALUE"""),"Pilihan 7") -> Pilihan 7 | T19: =IFERROR(__xludf.DUMMYFUNCTION("""COMPUTED_VALUE"""),3.0) -> 3
B20: =IFERROR(__xludf.DUMMYFUNCTION("""COMPUTED_VALUE"""),"Pengolahan Citra Digital") -> Pengolahan Citra Digital | D20: =IFERROR(__xludf.DUMMYFUNCTION("""COMPUTED_VALUE"""),3.0) -> 3 | J20: =IFERROR(__xludf.DUMMYFUNCTION("""COMPUTED_VALUE"""),"Kewirausahaan") -> Kewirausahaan | L20: =IFERROR(__xludf.DUMMYFUNCTION("""COMPUTED_VALUE"""),2.0) -> 2 | R20: =IFERROR(__xludf.DUMMYFUNCTION("""COMPUTED_VALUE"""),"Etika Profesi") -> Etika Profesi | T20: =IFERROR(__xludf.DUMMYFUNCTION("""COMPUTED_VALUE"""),2.0) -> 2
B21: =IFERROR(__xludf.DUMMYFUNCTION("""COMPUTED_VALUE"""),"Analisis Multivariat") -> Analisis Multivariat | D21: =IFERROR(__xludf.DUMMYFUNCTION("""COMPUTED_VALUE"""),3.0) -> 3 | J21: =IFERROR(__xludf.DUMMYFUNCTION("""COMPUTED_VALUE"""),"Pilihan 3") -> Pilihan 3 | L21: =IFERROR(__xludf.DUMMYFUNCTION("""COMPUTED_VALUE"""),3.0) -> 3 | R21: =IFERROR(__xludf.DUMMYFUNCTION("""COMPUTED_VALUE"""),"Kecerdasan Bisnis") -> Kecerdasan Bisnis | T21: =IFERROR(__xludf.DUMMYFUNCTION("""COMPUTED_VALUE"""),3.0) -> 3
B22: =IFERROR(__xludf.DUMMYFUNCTION("""COMPUTED_VALUE"""),"Pembelajaran Mesin Dasar") -> Pembelajaran Mesin Dasar | D22: =IFERROR(__xludf.DUMMYFUNCTION("""COMPUTED_VALUE"""),3.0) -> 3 | J22: =IFERROR(__xludf.DUMMYFUNCTION("""COMPUTED_VALUE"""),"Pilihan 4") -> Pilihan 4 | L22: =IFERROR(__xludf.DUMMYFUNCTION("""COMPUTED_VALUE"""),3.0) -> 3 | R22: =IFERROR(__xludf.DUMMYFUNCTION("""COMPUTED_VALUE"""),"SIM") -> SIM | T22: =IFERROR(__xludf.DUMMYFUNCTION("""COMPUTED_VALUE"""),3.0) -> 3
B23: =IFERROR(__xludf.DUMMYFUNCTION("""COMPUTED_VALUE"""),"Rekayasa Perangkat Lunak") -> Rekayasa Perangkat Lunak | D23: =IFERROR(__xludf.DUMMYFUNCTION("""COMPUTED_VALUE"""),3.0) -> 3 | J23: =IFERROR(__xludf.DUMMYFUNCTION("""COMPUTED_VALUE"""),"Pilihan 5") -> Pilihan 5 | L23: =IFERROR(__xludf.DUMMYFUNCTION("""COMPUTED_VALUE"""),3.0) -> 3 | R23: =IFERROR(__xludf.DUMMYFUNCTION("""COMPUTED_VALUE"""),"Manajemen Proyek") -> Manajemen Proyek | T23: =IFERROR(__xludf.DUMMYFUNCTION("""COMPUTED_VALUE"""),3.0) -> 3 | Y23: *
A24: * | B24: =IFERROR(__xludf.DUMMYFUNCTION("""COMPUTED_VALUE"""),"Pendidikan Jasmani dan Kebugaran") -> Pendidikan Jasmani dan Kebugaran | D24: =IFERROR(__xludf.DUMMYFUNCTION("""COMPUTED_VALUE"""),2.0) -> 2 | J24: =IFERROR(__xludf.DUMMYFUNCTION("""COMPUTED_VALUE"""),"Pilihan 6") -> Pilihan 6 | L24: =IFERROR(__xludf.DUMMYFUNCTION("""COMPUTED_VALUE"""),3.0) -> 3 | R24: =IFERROR(__xludf.DUMMYFUNCTION("""COMPUTED_VALUE"""),"Pilihan 8") -> Pilihan 8 | T24: =IFERROR(__xludf.DUMMYFUNCTION("""COMPUTED_VALUE"""),3.0) -> 3
H25: * | J25: =IFERROR(__xludf.DUMMYFUNCTION("""COMPUTED_VALUE"""),"Creative Thinking") -> Creative Thinking | L25: =IFERROR(__xludf.DUMMYFUNCTION("""COMPUTED_VALUE"""),2.0) -> 2
C26: * | J26: =IFERROR(__xludf.DUMMYFUNCTION("""COMPUTED_VALUE"""),"Bahasa Inggris") -> Bahasa Inggris | L26: =IFERROR(__xludf.DUMMYFUNCTION("""COMPUTED_VALUE"""),2.0) -> 2
F27: * | N27: *
R28: *
B29: Mata Kuliah | C29: Hari | D29: SKS | E29: Waktu | F29: Keterangan | G29: Kehadiran | H29: Progress | J29: Mata Kuliah | K29: Hari | L29: SKS | M29: Waktu | N29: Keterangan | O29: Kehadiran | P29: Progress | W29: * | Y29: *
B30: =IFERROR(__xludf.DUMMYFUNCTION("QUERY(Database!B7:J58, ""select C, D, E, F, G, H, I where B = 7"", 0) "),"Pembelajaran Mesin Lanjut") -> Pembelajaran Mesin Lanjut | D30: =IFERROR(__xludf.DUMMYFUNCTION("""COMPUTED_VALUE"""),3.0) -> 3 | J30: =IFERROR(__xludf.DUMMYFUNCTION("QUERY(Database!B7:J58, ""select C, D, E, F, G, H, I where B = 8"", 0) "),"Tugas Akhir") -> Tugas Akhir | L30: =IFERROR(__xludf.DUMMYFUNCTION("""COMPUTED_VALUE"""),4.0) -> 4
A31: * | B31: =IFERROR(__xludf.DUMMYFUNCTION("""COMPUTED_VALUE"""),"Analisis Big Data") -> Analisis Big Data | D31: =IFERROR(__xludf.DUMMYFUNCTION("""COMPUTED_VALUE"""),3.0) -> 3 | T31: *
B32: =IFERROR(__xludf.DUMMYFUNCTION("""COMPUTED_VALUE"""),"Graf Sains Data") -> Graf Sains Data | D32: =IFERROR(__xludf.DUMMYFUNCTION("""COMPUTED_VALUE"""),3.0) -> 3
B33: =IFERROR(__xludf.DUMMYFUNCTION("""COMPUTED_VALUE"""),"Pilihan 1") -> Pilihan 1 | D33: =IFERROR(__xludf.DUMMYFUNCTION("""COMPUTED_VALUE"""),3.0) -> 3 | I33: *
B34: =IFERROR(__xludf.DUMMYFUNCTION("""COMPUTED_VALUE"""),"Pilihan 2") -> Pilihan 2 | D34: =IFERROR(__xludf.DUMMYFUNCTION("""COMPUTED_VALUE"""),3.0) -> 3 | X34: *
B35: =IFERROR(__xludf.DUMMYFUNCTION("""COMPUTED_VALUE"""),"Proposal Tugas Akhir") -> Proposal Tugas Akhir | D35: =IFERROR(__xludf.DUMMYFUNCTION("""COMPUTED_VALUE"""),2.0) -> 2 | R35: * | W35: *
G39: *
C40: * | M40: *
O42: * | U42: *
K43: * | Q43: *
G44: *
B45: * | N45: * | X45: *
E46: *
...

Sheet Kalender 
A1: HOME | B1: DASHBOARD | C1: ENTRY DATA | D1: DATA BASE | E1: GRAPH | F1: JADWAL | G1: KALENDER | H1: TRACKER
C3: Year: | D3: 2025 | I3: Month: | J3: 7 | Q3: Start Day | R3: 1
AA4: Kalender Akademik UNESA
B6: =IF($J$3=1,D3,D3&"-"&D3+1) -> 2025-2026 | AA6: Tahun 2025/2026
B8: =DATE(D3,J3,1) -> 45839 | J8: =DATE(YEAR(B8+42),MONTH(B8+42),1) -> 45870 | R8: =DATE(YEAR(J8+42),MONTH(J8+42),1) -> 45901 | AA8: Jul. 1-21 | AB8: Permohonan Pindah/Mutasi internal Unesa
B9: =CHOOSE(1+MOD($R$3+1-2,7),"Su","M","Tu","W","Th","F","Sa") -> Su | C9: =CHOOSE(1+MOD($R$3+2-2,7),"Su","M","Tu","W","Th","F","Sa") -> M | D9: =CHOOSE(1+MOD($R$3+3-2,7),"Su","M","Tu","W","Th","F","Sa") -> Tu | E9: =CHOOSE(1+MOD($R$3+4-2,7),"Su","M","Tu","W","Th","F","Sa") -> W | F9: =CHOOSE(1+MOD($R$3+5-2,7),"Su","M","Tu","W","Th","F","Sa") -> Th | G9: =CHOOSE(1+MOD($R$3+6-2,7),"Su","M","Tu","W","Th","F","Sa") -> F | H9: =CHOOSE(1+MOD($R$3+7-2,7),"Su","M","Tu","W","Th","F","Sa") -> Sa | J9: =CHOOSE(1+MOD($R$3+1-2,7),"Su","M","Tu","W","Th","F","Sa") -> Su | K9: =CHOOSE(1+MOD($R$3+2-2,7),"Su","M","Tu","W","Th","F","Sa") -> M | L9: =CHOOSE(1+MOD($R$3+3-2,7),"Su","M","Tu","W","Th","F","Sa") -> Tu | M9: =CHOOSE(1+MOD($R$3+4-2,7),"Su","M","Tu","W","Th","F","Sa") -> W | N9: =CHOOSE(1+MOD($R$3+5-2,7),"Su","M","Tu","W","Th","F","Sa") -> Th | O9: =CHOOSE(1+MOD($R$3+6-2,7),"Su","M","Tu","W","Th","F","Sa") -> F | P9: =CHOOSE(1+MOD($R$3+7-2,7),"Su","M","Tu","W","Th","F","Sa") -> Sa | R9: =CHOOSE(1+MOD($R$3+1-2,7),"Su","M","Tu","W","Th","F","Sa") -> Su | S9: =CHOOSE(1+MOD($R$3+2-2,7),"Su","M","Tu","W","Th","F","Sa") -> M | T9: =CHOOSE(1+MOD($R$3+3-2,7),"Su","M","Tu","W","Th","F","Sa") -> Tu | U9: =CHOOSE(1+MOD($R$3+4-2,7),"Su","M","Tu","W","Th","F","Sa") -> W | V9: =CHOOSE(1+MOD($R$3+5-2,7),"Su","M","Tu","W","Th","F","Sa") -> Th | W9: =CHOOSE(1+MOD($R$3+6-2,7),"Su","M","Tu","W","Th","F","Sa") -> F | X9: =CHOOSE(1+MOD($R$3+7-2,7),"Su","M","Tu","W","Th","F","Sa") -> Sa | AA9: Jul. 15-30 | AB9: Persetujuan Pindah/Mutasi internal Unesa
B10: =IF(WEEKDAY(B8,1)=$R$3,B8,"") | C10: =IF(B10="",IF(WEEKDAY(B8,1)=MOD($R$3,7)+1,B8,""),B10+1) | D10: =IF(C10="",IF(WEEKDAY(B8,1)=MOD($R$3+1,7)+1,B8,""),C10+1) -> 45839 | E10: =IF(D10="",IF(WEEKDAY(B8,1)=MOD($R$3+2,7)+1,B8,""),D10+1) -> 45840 | F10: =IF(E10="",IF(WEEKDAY(B8,1)=MOD($R$3+3,7)+1,B8,""),E10+1) -> 45841 | G10: =IF(F10="",IF(WEEKDAY(B8,1)=MOD($R$3+4,7)+1,B8,""),F10+1) -> 45842 | H10: =IF(G10="",IF(WEEKDAY(B8,1)=MOD($R$3+5,7)+1,B8,""),G10+1) -> 45843 | J10: =IF(WEEKDAY(J8,1)=$R$3,J8,"") | K10: =IF(J10="",IF(WEEKDAY(J8,1)=MOD($R$3,7)+1,J8,""),J10+1) | L10: =IF(K10="",IF(WEEKDAY(J8,1)=MOD($R$3+1,7)+1,J8,""),K10+1) | M10: =IF(L10="",IF(WEEKDAY(J8,1)=MOD($R$3+2,7)+1,J8,""),L10+1) | N10: =IF(M10="",IF(WEEKDAY(J8,1)=MOD($R$3+3,7)+1,J8,""),M10+1) | O10: =IF(N10="",IF(WEEKDAY(J8,1)=MOD($R$3+4,7)+1,J8,""),N10+1) -> 45870 | P10: =IF(O10="",IF(WEEKDAY(J8,1)=MOD($R$3+5,7)+1,J8,""),O10+1) -> 45871 | R10: =IF(WEEKDAY(R8,1)=$R$3,R8,"") | S10: =IF(R10="",IF(WEEKDAY(R8,1)=MOD($R$3,7)+1,R8,""),R10+1) -> 45901 | T10: =IF(S10="",IF(WEEKDAY(R8,1)=MOD($R$3+1,7)+1,R8,""),S10+1) -> 45902 | U10: =IF(T10="",IF(WEEKDAY(R8,1)=MOD($R$3+2,7)+1,R8,""),T10+1) -> 45903 | V10: =IF(U10="",IF(WEEKDAY(R8,1)=MOD($R$3+3,7)+1,R8,""),U10+1) -> 45904 | W10: =IF(V10="",IF(WEEKDAY(R8,1)=MOD($R$3+4,7)+1,R8,""),V10+1) -> 45905 | X10: =IF(W10="",IF(WEEKDAY(R8,1)=MOD($R$3+5,7)+1,R8,""),W10+1) -> 45906 | AA10: Jul. 21-31 | AB10: Masa Pengajuan Cuti
B11: =IF(H10="","",IF(MONTH(H10+1)<>MONTH(H10),"",H10+1)) -> 45844 | C11: =IF(B11="","",IF(MONTH(B11+1)<>MONTH(B11),"",B11+1)) -> 45845 | D11: =IF(C11="","",IF(MONTH(C11+1)<>MONTH(C11),"",C11+1)) -> 45846 | E11: =IF(D11="","",IF(MONTH(D11+1)<>MONTH(D11),"",D11+1)) -> 45847 | F11: =IF(E11="","",IF(MONTH(E11+1)<>MONTH(E11),"",E11+1)) -> 45848 | G11: =IF(F11="","",IF(MONTH(F11+1)<>MONTH(F11),"",F11+1)) -> 45849 | H11: =IF(G11="","",IF(MONTH(G11+1)<>MONTH(G11),"",G11+1)) -> 45850 | J11: =IF(P10="","",IF(MONTH(P10+1)<>MONTH(P10),"",P10+1)) -> 45872 | K11: =IF(J11="","",IF(MONTH(J11+1)<>MONTH(J11),"",J11+1)) -> 45873 | L11: =IF(K11="","",IF(MONTH(K11+1)<>MONTH(K11),"",K11+1)) -> 45874 | M11: =IF(L11="","",IF(MONTH(L11+1)<>MONTH(L11),"",L11+1)) -> 45875 | N11: =IF(M11="","",IF(MONTH(M11+1)<>MONTH(M11),"",M11+1)) -> 45876 | O11: =IF(N11="","",IF(MONTH(N11+1)<>MONTH(N11),"",N11+1)) -> 45877 | P11: =IF(O11="","",IF(MONTH(O11+1)<>MONTH(O11),"",O11+1)) -> 45878 | R11: =IF(X10="","",IF(MONTH(X10+1)<>MONTH(X10),"",X10+1)) -> 45907 | S11: =IF(R11="","",IF(MONTH(R11+1)<>MONTH(R11),"",R11+1)) -> 45908 | T11: =IF(S11="","",IF(MONTH(S11+1)<>MONTH(S11),"",S11+1)) -> 45909 | U11: =IF(T11="","",IF(MONTH(T11+1)<>MONTH(T11),"",T11+1)) -> 45910 | V11: =IF(U11="","",IF(MONTH(U11+1)<>MONTH(U11),"",U11+1)) -> 45911 | W11: =IF(V11="","",IF(MONTH(V11+1)<>MONTH(V11),"",V11+1)) -> 45912 | X11: =IF(W11="","",IF(MONTH(W11+1)<>MONTH(W11),"",W11+1)) -> 45913 | AA11: Jul. 14-31 | AB11: Pembayaran SPP/UKT mahasiswa lama
B12: =IF(H11="","",IF(MONTH(H11+1)<>MONTH(H11),"",H11+1)) -> 45851 | C12: =IF(B12="","",IF(MONTH(B12+1)<>MONTH(B12),"",B12+1)) -> 45852 | D12: =IF(C12="","",IF(MONTH(C12+1)<>MONTH(C12),"",C12+1)) -> 45853 | E12: =IF(D12="","",IF(MONTH(D12+1)<>MONTH(D12),"",D12+1)) -> 45854 | F12: =IF(E12="","",IF(MONTH(E12+1)<>MONTH(E12),"",E12+1)) -> 45855 | G12: =IF(F12="","",IF(MONTH(F12+1)<>MONTH(F12),"",F12+1)) -> 45856 | H12: =IF(G12="","",IF(MONTH(G12+1)<>MONTH(G12),"",G12+1)) -> 45857 | J12: =IF(P11="","",IF(MONTH(P11+1)<>MONTH(P11),"",P11+1)) -> 45879 | K12: =IF(J12="","",IF(MONTH(J12+1)<>MONTH(J12),"",J12+1)) -> 45880 | L12: =IF(K12="","",IF(MONTH(K12+1)<>MONTH(K12),"",K12+1)) -> 45881 | M12: =IF(L12="","",IF(MONTH(L12+1)<>MONTH(L12),"",L12+1)) -> 45882 | N12: =IF(M12="","",IF(MONTH(M12+1)<>MONTH(M12),"",M12+1)) -> 45883 | O12: =IF(N12="","",IF(MONTH(N12+1)<>MONTH(N12),"",N12+1)) -> 45884 | P12: =IF(O12="","",IF(MONTH(O12+1)<>MONTH(O12),"",O12+1)) -> 45885 | R12: =IF(X11="","",IF(MONTH(X11+1)<>MONTH(X11),"",X11+1)) -> 45914 | S12: =IF(R12="","",IF(MONTH(R12+1)<>MONTH(R12),"",R12+1)) -> 45915 | T12: =IF(S12="","",IF(MONTH(S12+1)<>MONTH(S12),"",S12+1)) -> 45916 | U12: =IF(T12="","",IF(MONTH(T12+1)<>MONTH(T12),"",T12+1)) -> 45917 | V12: =IF(U12="","",IF(MONTH(U12+1)<>MONTH(U12),"",U12+1)) -> 45918 | W12: =IF(V12="","",IF(MONTH(V12+1)<>MONTH(V12),"",V12+1)) -> 45919 | X12: =IF(W12="","",IF(MONTH(W12+1)<>MONTH(W12),"",W12+1)) -> 45920 | AA12: 45859 | AB12: Batas Akhir Ujian : Tugas Akhir, Skripsi, Disertasi
B13: =IF(H12="","",IF(MONTH(H12+1)<>MONTH(H12),"",H12+1)) -> 45858 | C13: =IF(B13="","",IF(MONTH(B13+1)<>MONTH(B13),"",B13+1)) -> 45859 | D13: =IF(C13="","",IF(MONTH(C13+1)<>MONTH(C13),"",C13+1)) -> 45860 | E13: =IF(D13="","",IF(MONTH(D13+1)<>MONTH(D13),"",D13+1)) -> 45861 | F13: =IF(E13="","",IF(MONTH(E13+1)<>MONTH(E13),"",E13+1)) -> 45862 | G13: =IF(F13="","",IF(MONTH(F13+1)<>MONTH(F13),"",F13+1)) -> 45863 | H13: =IF(G13="","",IF(MONTH(G13+1)<>MONTH(G13),"",G13+1)) -> 45864 | J13: =IF(P12="","",IF(MONTH(P12+1)<>MONTH(P12),"",P12+1)) -> 45886 | K13: =IF(J13="","",IF(MONTH(J13+1)<>MONTH(J13),"",J13+1)) -> 45887 | L13: =IF(K13="","",IF(MONTH(K13+1)<>MONTH(K13),"",K13+1)) -> 45888 | M13: =IF(L13="","",IF(MONTH(L13+1)<>MONTH(L13),"",L13+1)) -> 45889 | N13: =IF(M13="","",IF(MONTH(M13+1)<>MONTH(M13),"",M13+1)) -> 45890 | O13: =IF(N13="","",IF(MONTH(N13+1)<>MONTH(N13),"",N13+1)) -> 45891 | P13: =IF(O13="","",IF(MONTH(O13+1)<>MONTH(O13),"",O13+1)) -> 45892 | R13: =IF(X12="","",IF(MONTH(X12+1)<>MONTH(X12),"",X12+1)) -> 45921 | S13: =IF(R13="","",IF(MONTH(R13+1)<>MONTH(R13),"",R13+1)) -> 45922 | T13: =IF(S13="","",IF(MONTH(S13+1)<>MONTH(S13),"",S13+1)) -> 45923 | U13: =IF(T13="","",IF(MONTH(T13+1)<>MONTH(T13),"",T13+1)) -> 45924 | V13: =IF(U13="","",IF(MONTH(U13+1)<>MONTH(U13),"",U13+1)) -> 45925 | W13: =IF(V13="","",IF(MONTH(V13+1)<>MONTH(V13),"",V13+1)) -> 45926 | X13: =IF(W13="","",IF(MONTH(W13+1)<>MONTH(W13),"",W13+1)) -> 45927 | AA13: Aug. 1-8 | AB13: Unggah Jadwal Kuliah dan RPS
B14: =IF(H13="","",IF(MONTH(H13+1)<>MONTH(H13),"",H13+1)) -> 45865 | C14: =IF(B14="","",IF(MONTH(B14+1)<>MONTH(B14),"",B14+1)) -> 45866 | D14: =IF(C14="","",IF(MONTH(C14+1)<>MONTH(C14),"",C14+1)) -> 45867 | E14: =IF(D14="","",IF(MONTH(D14+1)<>MONTH(D14),"",D14+1)) -> 45868 | F14: =IF(E14="","",IF(MONTH(E14+1)<>MONTH(E14),"",E14+1)) -> 45869 | G14: =IF(F14="","",IF(MONTH(F14+1)<>MONTH(F14),"",F14+1)) | H14: =IF(G14="","",IF(MONTH(G14+1)<>MONTH(G14),"",G14+1)) | J14: =IF(P13="","",IF(MONTH(P13+1)<>MONTH(P13),"",P13+1)) -> 45893 | K14: =IF(J14="","",IF(MONTH(J14+1)<>MONTH(J14),"",J14+1)) -> 45894 | L14: =IF(K14="","",IF(MONTH(K14+1)<>MONTH(K14),"",K14+1)) -> 45895 | M14: =IF(L14="","",IF(MONTH(L14+1)<>MONTH(L14),"",L14+1)) -> 45896 | N14: =IF(M14="","",IF(MONTH(M14+1)<>MONTH(M14),"",M14+1)) -> 45897 | O14: =IF(N14="","",IF(MONTH(N14+1)<>MONTH(N14),"",N14+1)) -> 45898 | P14: =IF(O14="","",IF(MONTH(O14+1)<>MONTH(O14),"",O14+1)) -> 45899 | R14: =IF(X13="","",IF(MONTH(X13+1)<>MONTH(X13),"",X13+1)) -> 45928 | S14: =IF(R14="","",IF(MONTH(R14+1)<>MONTH(R14),"",R14+1)) -> 45929 | T14: =IF(S14="","",IF(MONTH(S14+1)<>MONTH(S14),"",S14+1)) -> 45930 | U14: =IF(T14="","",IF(MONTH(T14+1)<>MONTH(T14),"",T14+1)) | V14: =IF(U14="","",IF(MONTH(U14+1)<>MONTH(U14),"",U14+1)) | W14: =IF(V14="","",IF(MONTH(V14+1)<>MONTH(V14),"",V14+1)) | X14: =IF(W14="","",IF(MONTH(W14+1)<>MONTH(W14),"",W14+1)) | AA14: Aug. 11-20 | AB14: Evaluasi Hasil Studi mahasiswa
B15: =IF(H14="","",IF(MONTH(H14+1)<>MONTH(H14),"",H14+1)) | C15: =IF(B15="","",IF(MONTH(B15+1)<>MONTH(B15),"",B15+1)) | D15: =IF(C15="","",IF(MONTH(C15+1)<>MONTH(C15),"",C15+1)) | E15: =IF(D15="","",IF(MONTH(D15+1)<>MONTH(D15),"",D15+1)) | F15: =IF(E15="","",IF(MONTH(E15+1)<>MONTH(E15),"",E15+1)) | G15: =IF(F15="","",IF(MONTH(F15+1)<>MONTH(F15),"",F15+1)) | H15: =IF(G15="","",IF(MONTH(G15+1)<>MONTH(G15),"",G15+1)) | J15: =IF(P14="","",IF(MONTH(P14+1)<>MONTH(P14),"",P14+1)) -> 45900 | K15: =IF(J15="","",IF(MONTH(J15+1)<>MONTH(J15),"",J15+1)) | L15: =IF(K15="","",IF(MONTH(K15+1)<>MONTH(K15),"",K15+1)) | M15: =IF(L15="","",IF(MONTH(L15+1)<>MONTH(L15),"",L15+1)) | N15: =IF(M15="","",IF(MONTH(M15+1)<>MONTH(M15),"",M15+1)) | O15: =IF(N15="","",IF(MONTH(N15+1)<>MONTH(N15),"",N15+1)) | P15: =IF(O15="","",IF(MONTH(O15+1)<>MONTH(O15),"",O15+1)) | R15: =IF(X14="","",IF(MONTH(X14+1)<>MONTH(X14),"",X14+1)) | S15: =IF(R15="","",IF(MONTH(R15+1)<>MONTH(R15),"",R15+1)) | T15: =IF(S15="","",IF(MONTH(S15+1)<>MONTH(S15),"",S15+1)) | U15: =IF(T15="","",IF(MONTH(T15+1)<>MONTH(T15),"",T15+1)) | V15: =IF(U15="","",IF(MONTH(U15+1)<>MONTH(U15),"",U15+1)) | W15: =IF(V15="","",IF(MONTH(V15+1)<>MONTH(V15),"",V15+1)) | X15: =IF(W15="","",IF(MONTH(W15+1)<>MONTH(W15),"",W15+1)) | AA15: Aug. 11-15 | AB15: Kepenasihatan dan KRS mahasiswa lama
AA16: Jul. 29-31 | AB16: Masa Persetujuan Cuti
B17: =DATE(YEAR(R8+42),MONTH(R8+42),1) -> 45931 | J17: =DATE(YEAR(B17+42),MONTH(B17+42),1) -> 45962 | R17: =DATE(YEAR(J17+42),MONTH(J17+42),1) -> 45992 | AA17: Aug. 18-22 | AB17: Pengenalan Kehidupan (PKKMB)
B18: =CHOOSE(1+MOD($R$3+1-2,7),"Su","M","Tu","W","Th","F","Sa") -> Su | C18: =CHOOSE(1+MOD($R$3+2-2,7),"Su","M","Tu","W","Th","F","Sa") -> M | D18: =CHOOSE(1+MOD($R$3+3-2,7),"Su","M","Tu","W","Th","F","Sa") -> Tu | E18: =CHOOSE(1+MOD($R$3+4-2,7),"Su","M","Tu","W","Th","F","Sa") -> W | F18: =CHOOSE(1+MOD($R$3+5-2,7),"Su","M","Tu","W","Th","F","Sa") -> Th | G18: =CHOOSE(1+MOD($R$3+6-2,7),"Su","M","Tu","W","Th","F","Sa") -> F | H18: =CHOOSE(1+MOD($R$3+7-2,7),"Su","M","Tu","W","Th","F","Sa") -> Sa | J18: =CHOOSE(1+MOD($R$3+1-2,7),"Su","M","Tu","W","Th","F","Sa") -> Su | K18: =CHOOSE(1+MOD($R$3+2-2,7),"Su","M","Tu","W","Th","F","Sa") -> M | L18: =CHOOSE(1+MOD($R$3+3-2,7),"Su","M","Tu","W","Th","F","Sa") -> Tu | M18: =CHOOSE(1+MOD($R$3+4-2,7),"Su","M","Tu","W","Th","F","Sa") -> W | N18: =CHOOSE(1+MOD($R$3+5-2,7),"Su","M","Tu","W","Th","F","Sa") -> Th | O18: =CHOOSE(1+MOD($R$3+6-2,7),"Su","M","Tu","W","Th","F","Sa") -> F | P18: =CHOOSE(1+MOD($R$3+7-2,7),"Su","M","Tu","W","Th","F","Sa") -> Sa | R18: =CHOOSE(1+MOD($R$3+1-2,7),"Su","M","Tu","W","Th","F","Sa") -> Su | S18: =CHOOSE(1+MOD($R$3+2-2,7),"Su","M","Tu","W","Th","F","Sa") -> M | T18: =CHOOSE(1+MOD($R$3+3-2,7),"Su","M","Tu","W","Th","F","Sa") -> Tu | U18: =CHOOSE(1+MOD($R$3+4-2,7),"Su","M","Tu","W","Th","F","Sa") -> W | V18: =CHOOSE(1+MOD($R$3+5-2,7),"Su","M","Tu","W","Th","F","Sa") -> Th | W18: =CHOOSE(1+MOD($R$3+6-2,7),"Su","M","Tu","W","Th","F","Sa") -> F | X18: =CHOOSE(1+MOD($R$3+7-2,7),"Su","M","Tu","W","Th","F","Sa") -> Sa | AA18: Aug. 20-22 | AB18: Kepenasihatan dan KRS mahasiswa baru
